Workbook

Sheet RAG
A1: ID_PRODUCT | B1: PRODUCTO | C1: PRECIO | D1: ESTADO
A2: TV4827 | B2: Smart TV Samsung 55" 4K | C2: 650000 | D2: Publicado
A3: HE1093 | B3: Heladera Whirlpool No Frost 375L | C3: 980000 | D3: Publicado
A4: PC6215 | B4: PC de Escritorio HP i5 8GB/512GB | C4: 520000 | D4: En Revisión
A5: CO3348 | B5: Cocina Longvie 4 Hornallas | C5: 310000 | D5: Publicado
A6: NB7701 | B6: Notebook Lenovo IdeaPad i5 16GB | C6: 1350000 | D6: En Revisión
A7: LR2984 | B7: Lavarropas Drean 8kg Carga Frontal | C7: 580000 | D7: Publicado
A8: MO5162 | B8: Microondas BGH 25L Grill | C8: 185000 | D8: Publicado
A9: AA9037 | B9: Aire Acondicionado Split Philco 3000F | C9: 720000 | D9: Publicado
A10: AR4470 | B10: Aspiradora Robot Xiaomi Mi Robot | C10: 410000 | D10: Publicado
A11: CA8629 | B11: Cafetera Nespresso Essenza Mini | C11: 95000 | D11: Publicado

Sheet CLIENTS
A1: ID_SESSION | B1: NAME | C1: LAST_UPDATED | D1: SUMMARY | E1: STATUS | F1: KEY_DATA | G1: MESSAGE_COUNT
A2: 7155230411 | B2: Jonathan | C2: 2026-09-12T02:21:55.638+00:00 | D2: El cliente (Jonathan) expresó interés en comprar una heladera en múltiples mensajes. El agente le ofreció la Heladera Whirlpool No Frost 375L a $980.000 con envío bonificado. Jonathan no respondió con confirmación ni con preferencias adicionales (tipo, capacidad, presupuesto, medidas, marca). La conversación quedó sin avance: el cliente no confirmó si quiere esa heladera, no aclaró si busca otra opción, y no realizó ninguna acción concreta. También se mencionó un Microondas BGH 25L Grill a $185.000 en una consulta intermedia, pero no hubo seguimiento sobre ese producto. El caso está pendiente: el cliente no respondió los últimos mensajes del agente. | F2: ["Nombre del cliente: Jonathan","Producto principal de interés: Heladera","Opción ofrecida: Heladera Whirlpool No Frost 375L — $980.000 — Código HE1093","URL de compra heladera: https://www.tutienda.com/comprar/HE1093","Producto secundario mencionado: Microondas BGH 25L Grill — $185.000 — Código MO5162","URL de compra microondas: https://www.tutienda.com/comprar/MO5162","Envío bonificado: AMBA/CABA 48hs, interior 5 días hábiles","No se obtuvo información sobre: tipo de heladera, capacidad deseada, presupuesto, medidas, marca preferida","Estado: cliente no confirmó compra ni respondió últimos mensajes"] | G2: 7

Sheet REQUEST
A1: ID_REQUEST | B1: ID_PRODUCT | C1: ES_MULTIPRODUCTO | D1: ID_SESSION | E1: QUESTION | F1: ANSWER | G1: STATUS_RAW | H1: STATUS_NORMALIZADO | I1: estado_veredicto
A2: 1787145905881 | B2: CA8629 | C2: =FALSE() -> FALSE | D2: 7155230417 | E2: hola quiero una caftera | F2: Hola, gracias por tu consulta. En nuestro catálogo tenemos la siguiente opción: - Cafetera Nespresso Essenza Mini — $95.000 Es la única cafetera disponible en el catálogo. ¿Querés que la reserve o te envío más detalles del modelo? | G2: Aprobado | H2: APROBADO
A3: 1787152417600 | B3: AA9037 | C3: =FALSE() -> FALSE | D3: 7155230417 | E3: hola, quiero un aire acondicionado | F3: Hola, gracias por tu consulta. En nuestro catálogo tenemos: Aire Acondicionado Split Philco 3000F — $720.000. Es el único equipo de aire acondicionado disponible actualmente en el catálogo. ¿Querés que lo reserve o necesitás más información? | G3: Aprobado | H3: APROBADO
A4: 1787152640672 | B4: CA8629 | C4: =FALSE() -> FALSE | D4: 7155230417 | E4: hola, quiero comprar una cafetera | F4: Hola, gracias por tu consulta. En nuestro catálogo tenemos: Cafetera Nespresso Essenza Mini — $95.000. Es la única cafetera disponible actualmente en el catálogo. ¿Querés que la reserve o necesitás más información sobre el producto? | G4: Aprobado | H4: APROBADO
A5: 1787153341203 | B5: LR2984 | C5: =FALSE() -> FALSE | D5: 7155230417 | E5: me interesa saber sobre labarropas, que tenes a la venta? | F5: Hola, gracias por tu consulta. Tenemos disponible: Lavarropas Drean 8kg Carga Frontal — $580.000 (id: LR2984). Es el único lavarropas en el catálogo actualmente. ¿Querés que lo reserve o necesitás más información? | G5: Aprobado | H5: APROBADO
A6: 1787153379077 | B6: HE1093 | C6: =FALSE() -> FALSE | D6: 7155230417 | E6: quiero comprar una heladera ahora | F6: Hola, gracias por tu consulta. En nuestro catálogo tenemos la Heladera Whirlpool No Frost 375L — $980.000 (id: HE1093). Es la única heladera disponible actualmente en el catálogo. ¿Querés que la reserve o necesitás más información sobre pago/envío? | G6: Cancelado | H6: CANCELADO
A7: 1787153430478 | B7: TV4827,HE1093,CO3348,LR2984,MO5162,AA9037,AR4470,CA8629 | C7: =TRUE() -> TRUE | D7: 7155230417 | E7: necesito comprar algo, q podes venderme? | F7: Hola, gracias por consultarnos. Podemos ofrecerte estos productos del catálogo: - Smart TV Samsung 55" 4K — $650.000 (id: TV4827) - Heladera Whirlpool No Frost 375L — $980.000 (id: HE1093) - Cocina Longvie 4 Hornallas — $310.000 (id: CO3348) - Lavarropas Drean 8kg Carga Frontal — $580.000 (id: LR2984) - Microondas BGH 25L Grill — $185.000 (id: MO5162) - Aire Acondicionado Split Philco 3000F — $720.000 (id: AA9037) - Aspiradora Robot Xiaomi Mi Robot — $410.000 (id: AR4470) - Cafetera Nespresso Essenza Mini — $95.000 (id: CA8629) ¿Querés que te recomiende según tu presupuesto o necesidad (cocina, limpieza, clima, entretenimiento), o reservamos alguno? | G7: Aprobado | H7: APROBADO
A8: 1787153501197 | B8: AR4470 | C8: =FALSE() -> FALSE | D8: 7155230417 | E8: quiero una aspiradora | F8: Hola, gracias por tu consulta. En nuestro catálogo tenemos la Aspiradora Robot Xiaomi Mi Robot — $410.000 (id: AR4470). Es la única aspiradora disponible actualmente en el catálogo. ¿Querés que la reserve o necesitás más información sobre pago/envío? | G8: Aprobado | H8: APROBADO
A9: 1787153566084 | C9: =FALSE() -> FALSE | D9: 7155230417 | E9: quiero una notebook | F9: Hola, gracias por tu consulta. En este momento no contamos con notebooks en nuestro catálogo, por lo que no puedo brindarte precio ni modelo. Puedo avisarte cuando tengamos stock de notebooks o ayudarte a ver otras opciones del catálogo (Smart TV, heladera, lavarropas, microondas, aire, aspiradora, cafetera). ¿Querés que te avise cuando ingrese una notebook o preferís ver alternativas ahora? | G9: Aprobado | H9: APROBADO
A10: 1787155040915 | C10: =FALSE() -> FALSE | D10: 7155230417 | E10: davacsvsBwB | F10: Hola, gracias por tu mensaje. No pude identificar qué producto querés con "davacsvsBwB". ¿Podés aclararme qué tipo de producto buscás (por ejemplo: heladera, lavarropas, TV, microondas)? Si preferís, te envío el catálogo completo disponible ahora. | G10: Aprobado | H10: APROBADO
A11: 1787575086353 | C11: =FALSE() -> FALSE | D11: 7155230417 | E11: quiero comprar algo | F11: Perfecto — ¿qué tipo de producto querés comprar? Por ejemplo: heladera, lavarropas, aire acondicionado, cocina/estufa, microondas, televisor, aspiradora u otro. Si ya tenés marca, tamaño/capacidad o un rango de precio avisame también. | G11: Cancelado | H11: CANCELADO
A12: 1787575810253 | B12: CA8629 | C12: =FALSE() -> FALSE | D12: 7155230417 | E12: algo para preparar infusiones | F12: Encontré: Cafetera Nespresso Essenza Mini — $95.000. Como alternativa disponible para calentar agua está el Microondas BGH 25L Grill — $185.000. ¿Querés que te prepare el presupuesto formal con alguno de estos? | G12: Aprobado | H12: APROBADO
A13: 1787576938484 | B13: CA8629 | C13: =FALSE() -> FALSE | D13: 7155230417 | E13: quiero comprar algo de menos de $100.000 | F13: Perfecto — encontré: Cafetera Nespresso Essenza Mini — $95.000. Es la única opción en el catálogo por debajo de $100.000. Como alternativa (más cara) está el Microondas BGH 25L Grill — $185.000. ¿Querés que te prepare el presupuesto formal de la cafetera? | G13: Cancelado | H13: CANCELADO
A14: 1787577014582 | B14: CA8629 | C14: =FALSE() -> FALSE | D14: 7155230417 | E14: quiero comprar algo de menos de $100.000 | F14: Encontré: Cafetera Nespresso Essenza Mini — $95.000 (ID: CA8629). Es la única opción en el catálogo por debajo de $100.000. Alternativa disponible fuera del rango: Microondas BGH 25L Grill — $185.000 (ID: MO5162). ¿Querés que te prepare el presupuesto formal de la cafetera? | G14: en analisis | H14: EN_PROCESO
A15: 1787577108365 | C15: =FALSE() -> FALSE | D15: 7155230417 | E15: quiero comprar algo, que me recomendas? | F15: Genial — para recomendarte mejor, ¿qué tipo de producto buscás? Elegí una de estas opciones o contame presupuesto y uso: 1) Televisor, 2) Heladera, 3) Cocina/anafe, 4) Lavarropas, 5) Microondas, 6) Aire acondicionado, 7) Aspiradora robot, 8) Cafetera. También podés decirme un rango de precio o si lo querés para casa pequeña, departamento, cocina completa, etc. | G15: Respuesta Automatica | H15: EN_PROCESO
A16: 1787577154752 | B16: TV4827 | C16: =FALSE() -> FALSE | D16: 7155230417 | E16: quiero el presupuesto de la tv | F16: Perfecto — encontré: Smart TV Samsung 55" 4K — $650.000 (ID: TV4827). Es la única TV publicada en el catálogo actualmente. ¿Querés que te prepare el presupuesto formal (incluyendo opciones de pago y envío)? | G16: Aprobado | H16: APROBADO
A17: 1787578892366 | B17: MO5162 | C17: =FALSE() -> FALSE | D17: 7155230417 | E17: hola quiero un microondas | F17: ¡Hola! 👋 Encontramos esto para vos: 🍽️ Microondas BGH 25L Grill 💰 $185.000 🚚 Envío por Correo Argentino: • AMBA y Capital Federal: 48 hs • Interior del país: 5 días hábiles • ¡El envío está bonificado con la compra! 🎉 🛒 Comprá ahora mismo en nuestra web: 👉 https://www.tutienda.com/comprar/MO5162 | G17: Aprobado | H17: APROBADO
A18: 1787699114763 | C18: =FALSE() -> FALSE | D18: 7155230417 | E18: hola quiero comprar algo | F18: ¡Hola! 👋 ¿Qué te gustaría comprar? Para ayudarte mejor, contame por favor: 1) Tipo de producto (elegí una): 🧊 Heladera, 🧺 Lavarropa, 🔥 Cocina/Anafe, 🍽️ Microondas, ❄️ Aire acondicionado, 📺 TV, 💡 Pequeños electrodomésticos u Otro. 2) Marca preferida y/o capacidad/tamaño (si lo sabés). 3) Presupuesto aproximado o rango de precio. 4) Dónde lo recibirías: AMBA/Capital Federal o Interior del país. Ejemplo de respuesta: "Heladera, Whirlpool, 300L, hasta $250000, AMBA" | G18: Respuesta Automatica | H18: EN_PROCESO
A19: 1787699136603 | B19: HE1093 | C19: =FALSE() -> FALSE | D19: 7155230411 | E19: una heladera | F19: ¡Perfecto! 🧊 Te paso el presupuesto de la heladera que tenemos disponible: • Heladera Whirlpool No Frost 375L — $980.000 🚚 Envío por Correo Argentino: • AMBA y Capital Federal: 48 hs • Interior del país: 5 días hábiles • ¡El envío está bonificado con la compra! 🎉 🛒 Comprá ahora mismo en nuestra web: 👉 https://www.tutienda.com/comprar/HE1093 ¿Querés que te gestione la reserva o preferís que un asesor te contacte para coordinar detalles? 🤝 | G19: Aprobado | H19: APROBADO
A20: 1787746190670 | C20: =FALSE() -> FALSE | D20: 7155230411 | E20: quiero comprar un producto | F20: ¡Perfecto! ¿Qué producto querés comprar? Podés decirme la categoría o modelo (por ejemplo: heladera, lavarropas, TV, aire acondicionado, microondas, etc.). Algunas preguntas rápidas para afinar la búsqueda: • ¿Tenés alguna marca preferida? • ¿Qué capacidad o tamaño necesitás (ej. 300L, 8 kg, 55")? • ¿Cuál es tu rango de presupuesto aproximado? • ¿Querés envío e instalación? Respondeme con cualquiera de estos datos y busco las opciones disponibles. | G20: Respuesta Automatica | H20: EN_PROCESO
A21: 1787747414597 | B21: MO5162 | C21: =FALSE() -> FALSE | D21: 7155230411 | E21: quiero un microondas | F21: 🔎 Encontré este microondas para vos: • Microondas BGH 25L Grill - Capacidad: 25 L - Función: Grill - Precio: $185.000 - Código: MO5162 🛒 Comprá ahora mismo en nuestra web: 👉 https://www.tutienda.com/comprar/MO5162 🚚 Envío por Correo Argentino: • AMBA y Capital Federal: 48 hs • Interior del país: 5 días hábiles • ¡El envío está bonificado con la compra! 🎉 ¿Querés que lo reserve y te contacte para coordinar pago y envío? 😊 | G21: Aprobado | H21: APROBADO
A22: 58576891-ad4f1987-df5f03e2 | C22: =FALSE() -> FALSE | D22: 7155230411 | E22: hola quiero comprar una heladera | F22: ¡Hola Jonathan! 👋 Gracias por escribir. Para recomendarte la heladera ideal, ¿podés decirme qué preferís? Respondé con los números o la info que tengas: 1) Tipo: • 1 — Freezer arriba (2 puertas) 🧊 • 2 — Combi / freezer abajo 🧊 • 3 — No-Frost (sin escarcha) ❄️ • 4 — Side-by-side / French door (gran capacidad) 🚪 2) Capacidad aproximada: • A — 200–300 L (pareja / departamento) • B — 300–500 L (familia) • C — >500 L (muy grande) 3) ¿Tenés preferencia de marca o color? 4) ¿Necesitás que tenga medidas exactas para que entre en un hueco? (alto x ancho x profundo) 5) ¿Cuál es tu presupuesto aproximado? Contame lo que puedas y yo busco modelos y precios publicados. 🧊 | G22: PEDIR_INFORMACION | H22: EN_PROCESO
A23: 58bffee1-ac6fb18f-74110d78 | B23: HE1093 | C23: =FALSE() -> FALSE | D23: 7155230411 | E23: hola quiero comprar una heladera | F23: ¡Hola Jonathan! 👋 ¡Qué gusto tenerte por acá! Encontré la siguiente heladera disponible en nuestro catálogo: 🧊 **Heladera Whirlpool No Frost 375L** 💰 Precio: **$980.000** 🚚 Envío por Correo Argentino: • AMBA y Capital Federal: 48 hs • Interior del país: 5 días hábiles • ¡El envío está bonificado con la compra! 🎉 🛒 Comprá ahora mismo en nuestra web: 👉 https://www.tutienda.com/comprar/HE1093 ¿Te interesa avanzar con esta opción, Jonathan? Un representante de nuestro equipo va a revisar tu consulta y te va a confirmar todo en breve. 😊 | G23: ENVIAR_PROPUESTA | H23: EN_PROCESO
A24: 92a3d151-ef88f289-75e5b709 | B24: HE1093 | C24: =FALSE() -> FALSE | D24: 7155230411 | E24: Quiero comprar una heladera | F24: ¡Hola Jonathan! 👋 ¡Qué bueno saber que querés avanzar con la heladera! 🧊 Te comparto nuevamente el detalle de la opción que tenemos disponible: 🧊 **Heladera Whirlpool No Frost 375L** 💰 Precio: **$980.000** 🚚 Envío por Correo Argentino: • AMBA y Capital Federal: 48 hs • Interior del país: 5 días hábiles • ¡El envío está bonificado con la compra! 🎉 🛒 Comprá ahora mismo en nuestra web: 👉 https://www.tutienda.com/comprar/HE1093 ¿Querés que un representante te contacte para confirmar la compra o tenés alguna otra consulta? 😊 | G24: APROBADO | H24: APROBADO
A25: 936b5ebf-d5d7f78e-109d62c3 | B25: HE1093 | C25: =FALSE() -> FALSE | D25: 7155230411 | E25: Quiero comprar una heladera | F25: ¡Hola Jonathan! 👋 ¡Qué bueno verte de nuevo por acá! Te cuento que la última vez estuvimos charlando sobre heladeras y te había acercado una opción que puede interesarte. 😊 🧊 **Heladera Whirlpool No Frost 375L** 💰 Precio: **$980.000** ✅ Disponible 🚚 Envío por Correo Argentino: • AMBA y Capital Federal: 48 hs • Interior del país: 5 días hábiles • ¡El envío está bonificado con la compra! 🎉 🛒 Comprá ahora mismo en nuestra web: 👉 https://www.tutienda.com/comprar/HE1093 ¿Querés avanzar con esta opción, o preferís que te busque alternativas? ¡Estoy acá para ayudarte! 💪 | G25: ENVIAR_PROPUESTA | H25: EN_PROCESO
A26: c0fe9047-99fa3648-73445af0 | B26: MO5162 | C26: =FALSE() -> FALSE | D26: 7155230411 | E26: quiero comprar un microondas | F26: ¡Hola Jonathan! 👋 ¡Excelente elección! 🎉 Tenemos justo lo que estás buscando: --- 📦 **Microondas BGH 25L Grill** 💰 Precio: **$185.000** ✅ Con función Grill incluida ✅ Listo para usar apenas lo recibís — ¡sin instalación técnica necesaria! --- 🚚 Envío por Correo Argentino: • AMBA y Capital Federal: 48 hs • Interior del país: 5 días hábiles • ¡El envío está bonificado con la compra! 🎉 --- 🛒 Comprá ahora mismo en nuestra web: 👉 https://www.tutienda.com/comprar/MO5162 ¿Querés que también te confirme el presupuesto de la heladera que habíamos visto antes? 😊 | G26: ENVIAR_PROPUESTA | H26: EN_PROCESO | I26: ACEPTADO
A27: c19cd117-32043124-cd1fcd12 | B27: MO5162 | C27: =FALSE() -> FALSE | D27: 7155230411 | E27: quiero comprar un microondas | F27: ¡Hola Jonathan! 👋 ¡Buenas noticias! Ya tenemos el microondas que buscás. Te armo el presupuesto ahora mismo 😊 --- 📦 **Microondas BGH 25L Grill** 💰 Precio: **$185.000** ✅ Disponibilidad: En stock --- 🚚 Envío por Correo Argentino: • AMBA y Capital Federal: 48 hs • Interior del país: 5 días hábiles • ¡El envío está bonificado con la compra! 🎉 --- 🛒 Comprá ahora mismo en nuestra web: 👉 https://www.tutienda.com/comprar/MO5162 ¿Tenés alguna consulta adicional? ¡Estoy a tu disposición! 😊 | G27: ENVIAR_PROPUESTA | H27: EN_PROCESO | I27: ACEPTADO
C28: =FALSE() -> FALSE | F28: ¡Hola Jonathan! 👋 ¿En qué producto de electrodomésticos estás interesado? Por favor, dime el nombre o la categoría y con gusto te envío el presupuesto. | G28: PEDIR_INFORMACION | H28: EN_PROCESO

Sheet JUDGE
A1: ID_REQUEST | B1: QUESTION | C1: ANSWER | D1: CONTEXT | E1: UMBRAL | F1: inconsistencias_detectadas | G1: afirmaciones_sin_respaldo | H1: justificacion | I1: categoria_error | J1: exactitud_factual | K1: estado_veredicto | L1: critica | M1: verbosidad_excesiva | N1: TRYS | O1: datetime
F2: [] | G2: [] | H2: La respuesta propuesta está vacía y no contiene contenido evaluable. Esto activa causal de rechazo automático por ausencia total de respuesta. | I2: AFIRMACION_SIN_RESPALDO | J2: 1 | K2: RECHAZADO | M2: =FALSE() -> FALSE | N2: 1 | O2: 2026-09-21T01:20:13.933+00:00
A3: c0fe9047-99fa3648-73445af0 | B3: quiero comprar un microondas | C3: ¡Hola Jonathan! 👋 ¡Excelente elección! 🎉 Tenemos justo lo que estás buscando: --- 📦 **Microondas BGH 25L Grill** 💰 Precio: **$185.000** ✅ Con función Grill incluida ✅ Listo para usar apenas lo recibís — ¡sin instalación técnica necesaria! --- 🚚 Envío por Correo Argentino: • AMBA y Capital Federal: 48 hs • Interior del país: 5 días hábiles • ¡El envío está bonificado con la compra! 🎉 --- 🛒 Comprá ahora mismo en nuestra web: 👉 https://www.tutienda.com/comprar/MO5162 ¿Querés que también te confirme el presupuesto de la heladera que habíamos visto antes? 😊 | D3: El cliente (Jonathan) expresó interés en comprar una heladera en múltiples mensajes. El agente le ofreció la Heladera Whirlpool No Frost 375L a $980.000 con envío bonificado. Jonathan no respondió con confirmación ni con preferencias adicionales (tipo, capacidad, presupuesto, medidas, marca). La conversación quedó sin avance: el cliente no confirmó si quiere esa heladera, no aclaró si busca otra opción, y no realizó ninguna acción concreta. También se mencionó un Microondas BGH 25L Grill a $185.000 en una consulta intermedia, pero no hubo seguimiento sobre ese producto. El caso está pendiente: el cliente no respondió los últimos mensajes del agente. | E3: 5 | F3: ["El contexto recuperado menciona un Microondas BGH 25L Grill a $185.000, pero no aporta respaldo para la afirmación adicional de que tiene función Grill incluida ni para que esté listo para usar sin instalación técnica necesaria."] | G3: ["Con función Grill incluida","Listo para usar apenas lo recibís — sin instalación técnica necesaria"] | H3: El producto y el precio principales coinciden con el contexto recuperado, por lo que el núcleo del presupuesto está sostenido. Sin embargo, la respuesta agrega dos afirmaciones técnicas adicionales que no aparecen respaldadas en el contexto y podrían inducir a error. | I3: AFIRMACION_SIN_RESPALDO | J3: 3 | K3: CORREGIR | L3: El producto y el precio están bien, pero eliminá o respaldá las afirmaciones técnicas adicionales que no figuran en el contexto recuperado. | M3: =FALSE() -> FALSE | N3: 1 | O3: 2026-09-21T01:20:41.367+00:00
A4: c19cd117-32043124-cd1fcd12 | B4: quiero comprar un microondas | C4: ¡Hola Jonathan! 👋 ¡Qué buena elección! 🍿 Tenemos el microondas ideal para vos: --- 📦 **Microondas BGH 25L Grill** 💰 Precio: **$185.000** ✅ ¡Disponible ahora! --- 🚚 Envío por Correo Argentino: • AMBA y Capital Federal: 48 hs • Interior del país: 5 días hábiles • ¡El envío está bonificado con la compra! 🎉 🛒 Comprá ahora mismo en nuestra web: 👉 https://www.tutienda.com/comprar/MO5162 --- 💳 Además, podés pagarlo en hasta **12 cuotas sin interés** con tarjetas de crédito de bancos adheridos, o con un **10% de descuento adicional** pagando por transferencia bancaria. 💸 ¿Querés avanzar con este microondas, Jonathan? ¡Estoy para ayudarte! 😊 | D4: El cliente (Jonathan) expresó interés en comprar una heladera en múltiples mensajes. El agente le ofreció la Heladera Whirlpool No Frost 375L a $980.000 con envío bonificado. Jonathan no respondió con confirmación ni con preferencias adicionales (tipo, capacidad, presupuesto, medidas, marca). La conversación quedó sin avance: el cliente no confirmó si quiere esa heladera, no aclaró si busca otra opción, y no realizó ninguna acción concreta. También se mencionó un Microondas BGH 25L Grill a $185.000 en una consulta intermedia, pero no hubo seguimiento sobre ese producto. El caso está pendiente: el cliente no respondió los últimos mensajes del agente. | E4: 5 | F4: [] | G4: ["podés pagarlo en hasta 12 cuotas sin interés con tarjetas de crédito de bancos adheridos","con un 10% de descuento adicional pagando por transferencia bancaria"] | H4: El producto y el precio del microondas coinciden con el contexto recuperado. Sin embargo, la respuesta agrega condiciones de pago y descuento que no aparecen en el contexto y podrían inducir a error. El resto del contenido estructural obligatorio no se evalúa como inconsistencia. | I4: AFIRMACION_SIN_RESPALDO | J4: 3 | K4: CORREGIR | L4: El producto y el precio están bien, pero eliminá las condiciones de pago y el descuento porque no figuran en el contexto recuperado. | M4: =FALSE() -> FALSE | N4: 1 | O4: 2026-09-21T01:39:20.413+00:00
A5: c19cd117-32043124-cd1fcd12 | B5: quiero comprar un microondas | C5: ¡Hola Jonathan! 👋 ¡Perfecto, te ayudo con el microondas! Tenemos disponible la siguiente opción: 📦 **Microondas BGH 25L Grill** 💰 Precio: **$185.000** ✅ Disponibilidad: En stock 🚚 Envío por Correo Argentino: • AMBA y Capital Federal: 48 hs • Interior del país: 5 días hábiles • ¡El envío está bonificado con la compra! 🎉 🛒 Comprá ahora mismo en nuestra web: 👉 https://www.tutienda.com/comprar/MO5162 ¿Te interesa este modelo? ¡Cualquier duda estoy acá! 😊 | D5: El cliente (Jonathan) expresó interés en comprar una heladera en múltiples mensajes. El agente le ofreció la Heladera Whirlpool No Frost 375L a $980.000 con envío bonificado. Jonathan no respondió con confirmación ni con preferencias adicionales (tipo, capacidad, presupuesto, medidas, marca). La conversación quedó sin avance: el cliente no confirmó si quiere esa heladera, no aclaró si busca otra opción, y no realizó ninguna acción concreta. También se mencionó un Microondas BGH 25L Grill a $185.000 en una consulta intermedia, pero no hubo seguimiento sobre ese producto. El caso está pendiente: el cliente no respondió los últimos mensajes del agente. | E5: 5 | F5: [] | G5: [] | H5: La respuesta ofrece un microondas y un precio que aparecen en el contexto recuperado. El resto corresponde a contenido estructural exento o a tono comercial habitual, por lo que no hay discrepancias factuales relevantes. | I5: NINGUNA | J5: 5 | K5: ACEPTADO | M5: =FALSE() -> FALSE | N5: 1 | O5: 2026-09-21T01:41:01.670+00:00
A6: c19cd117-32043124-cd1fcd12 | B6: quiero comprar un microondas | C6: ¡Hola Jonathan! 👋 ¡Buenas noticias! Ya tenemos el microondas que buscás. Te armo el presupuesto ahora mismo 😊 --- 📦 **Microondas BGH 25L Grill** 💰 Precio: **$185.000** ✅ Disponibilidad: En stock --- 🚚 Envío por Correo Argentino: • AMBA y Capital Federal: 48 hs • Interior del país: 5 días hábiles • ¡El envío está bonificado con la compra! 🎉 --- 🛒 Comprá ahora mismo en nuestra web: 👉 https://www.tutienda.com/comprar/MO5162 ¿Tenés alguna consulta adicional? ¡Estoy a tu disposición! 😊 | D6: El cliente (Jonathan) expresó interés en comprar una heladera en múltiples mensajes. El agente le ofreció la Heladera Whirlpool No Frost 375L a $980.000 con envío bonificado. Jonathan no respondió con confirmación ni con preferencias adicionales (tipo, capacidad, presupuesto, medidas, marca). La conversación quedó sin avance: el cliente no confirmó si quiere esa heladera, no aclaró si busca otra opción, y no realizó ninguna acción concreta. También se mencionó un Microondas BGH 25L Grill a $185.000 en una consulta intermedia, pero no hubo seguimiento sobre ese producto. El caso está pendiente: el cliente no respondió los últimos mensajes del agente. | E6: 5 | F6: [] | G6: [] | H6: La respuesta menciona un microondas y un precio que aparecen en el contexto recuperado, y el ID del enlace también coincide con el producto referido. El bloque de envío y la mención de stock forman parte del contenido estructural exento, por lo que no afectan la evaluación factual. | I6: NINGUNA | J6: 5 | K6: ACEPTADO | M6: =FALSE() -> FALSE | N6: 1 | O6: 2026-09-21T01:50:35.059+00:00
A7: c19cd117-32043124-cd1fcd12 | B7: quiero comprar un microondas | C7: ¡Hola Jonathan! 👋 ¡Buenas noticias! Ya tenemos el microondas que buscás. Te armo el presupuesto ahora mismo 😊 --- 📦 **Microondas BGH 25L Grill** 💰 Precio: **$185.000** ✅ Disponibilidad: En stock --- 🚚 Envío por Correo Argentino: • AMBA y Capital Federal: 48 hs • Interior del país: 5 días hábiles • ¡El envío está bonificado con la compra! 🎉 --- 🛒 Comprá ahora mismo en nuestra web: 👉 https://www.tutienda.com/comprar/MO5162 ¿Tenés alguna consulta adicional? ¡Estoy a tu disposición! 😊 | D7: El cliente (Jonathan) expresó interés en comprar una heladera en múltiples mensajes. El agente le ofreció la Heladera Whirlpool No Frost 375L a $980.000 con envío bonificado. Jonathan no respondió con confirmación ni con preferencias adicionales (tipo, capacidad, presupuesto, medidas, marca). La conversación quedó sin avance: el cliente no confirmó si quiere esa heladera, no aclaró si busca otra opción, y no realizó ninguna acción concreta. También se mencionó un Microondas BGH 25L Grill a $185.000 en una consulta intermedia, pero no hubo seguimiento sobre ese producto. El caso está pendiente: el cliente no respondió los últimos mensajes del agente. | E7: 5 | F7: [] | G7: [] | H7: La respuesta menciona un microondas y un precio que aparecen en el contexto recuperado, y el resto corresponde a contenido estructural exento o tono comercial. No se detectan discrepancias factuales relevantes respecto del contexto disponible. | I7: NINGUNA | J7: 5 | K7: ACEPTADO | M7: =FALSE() -> FALSE | N7: 1 | O7: 2026-09-21T02:02:51.271+00:00

Sheet WORKER
A1: ID_REQUEST | B1: DATE_TIME | C1: WORKER | D1: CODE
B2: 2026-08-31T17:50:35.766+00:00 | C2: OBSERVABILIDAD | D2: 200
B3: 2026-08-31T17:52:01.693+00:00 | C3: OBSERVABILIDAD | D3: 200
A4: 59009129-4e476787-9b8a6bdd | B4: 2026-08-31T18:07:15.269+00:00 | C4: OBSERVABILIDAD | D4: 200
B5: 2026-08-31T18:21:59.574+00:00 | C5: SUMMARY | D5: 200
A6: 590f8333-a9b56389-cf277059 | B6: 2026-08-31T18:23:14.315+00:00 | C6: OBSERVABILIDAD | D6: 200
A7: 590f8333-a9b56389-cf277059 | B7: 2026-08-31T18:23:24.938+00:00 | C7: SUMMARY | D7: 200
A8: 591075bb-4e6acc9d-340da384 | B8: 2026-08-31T18:24:16.771+00:00 | C8: OBSERVABILIDAD | D8: 200
A9: 591075bb-4e6acc9d-340da384 | B9: 2026-08-31T18:24:29.315+00:00 | C9: SUMMARY | D9: 200
A10: 5911338b-9d191349-4a395e82 | B10: 2026-08-31T18:25:09.079+00:00 | C10: OBSERVABILIDAD | D10: 200
A11: 5911338b-9d191349-4a395e82 | B11: 2026-08-31T18:25:21.503+00:00 | C11: SUMMARY | D11: 200
A12: 5911338b-9d191349-4a395e82 | B12: 2026-08-31T18:25:23.351+00:00 | C12: OBSERVABILIDAD | D12: 200
A13: 739c9188-287ab9ec-540e9d19 | B13: 2026-09-05T22:10:12.972+00:00 | C13: OBSERVABILIDAD | D13: 200
A14: 739c9188-287ab9ec-540e9d19 | B14: 2026-09-05T22:12:02.275+00:00 | C14: SUMMARY | D14: 200
A15: 739c9188-287ab9ec-540e9d19 | B15: 2026-09-05T22:13:17.146+00:00 | C15: OBSERVABILIDAD | D15: 200
A16: 73fffa72-d574002d-32c698a7 | B16: 2026-09-05T23:56:09.525+00:00 | C16: OBSERVABILIDAD | D16: 200
A17: 73fffa72-d574002d-32c698a7 | B17: 2026-09-05T23:56:23.604+00:00 | C17: SUMMARY | D17: 200
... A40: 936b5ebf-d5d7f78e-109d62c3 | B40: 2026-09-12T02:21:58.110+00:00 | C40: OBSERVABILIDAD | D40: 200
B41: 2026-09-20T22:01:19.854+00:00 | C41: JUDGE | D41: 200
A42: c0fe9047-99fa3648-73445af0 | B42: 2026-09-20T22:45:33.707+00:00 | C42: OBSERVABILIDAD | D42: 200
A43: c0fe9047-99fa3648-73445af0 | B43: 2026-09-20T22:47:55.498+00:00 | C43: JUDGE | D43: 200
B44: 2026-09-20T22:53:04.988+00:00 | C44: JUDGE | D44: 200
A45: c0fe9047-99fa3648-73445af0 | B45: 2026-09-20T22:54:35.532+00:00 | C45: JUDGE | D45: 200
B46: 2026-09-20T22:55:39.798+00:00 | C46: JUDGE | D46: 200
A47: c0fe9047-99fa3648-73445af0 | B47: 2026-09-20T22:56:23.163+00:00 | C47: JUDGE | D47: 200
A48: c0fe9047-99fa3648-73445af0 | B48: 2026-09-20T23:02:24.254+00:00 | C48: JUDGE | D48: 200
A49: c0fe9047-99fa3648-73445af0 | B49: 2026-09-20T23:09:37.676+00:00 | C49: JUDGE | D49: 200
A50: c0fe9047-99fa3648-73445af0 | B50: 2026-09-20T23:17:13.969+00:00 | C50: OBSERVABILIDAD | D50: 200
A51: c0fe9047-99fa3648-73445af0 | B51: 2026-09-20T23:17:16.761+00:00 | C51: JUDGE | D51: 200
A52: c0fe9047-99fa3648-73445af0 | B52: 2026-09-21T01:06:49.254+00:00 | C52: OBSERVABILIDAD | D52: 200
B53: 2026-09-21T01:20:16.174+00:00 | C53: JUDGE | D53: 200
A54: c0fe9047-99fa3648-73445af0 | B54: 2026-09-21T01:20:42.232+00:00 | C54: JUDGE | D54: 200
A55: c19cd117-32043124-cd1fcd12 | B55: 2026-09-21T01:39:17.410+00:00 | C55: OBSERVABILIDAD | D55: 200
A56: c19cd117-32043124-cd1fcd12 | B56: 2026-09-21T01:39:21.276+00:00 | C56: JUDGE | D56: 200
A57: c19cd117-32043124-cd1fcd12 | B57: 2026-09-21T01:40:58.102+00:00 | C57: OBSERVABILIDAD | D57: 200
A58: c19cd117-32043124-cd1fcd12 | B58: 2026-09-21T01:41:02.548+00:00 | C58: JUDGE | D58: 200
A59: c19cd117-32043124-cd1fcd12 | B59: 2026-09-21T01:50:32.254+00:00 | C59: OBSERVABILIDAD | D59: 200
A60: c19cd117-32043124-cd1fcd12 | B60: 2026-09-21T01:50:35.950+00:00 | C60: JUDGE | D60: 200
A61: c19cd117-32043124-cd1fcd12 | B61: 2026-09-21T02:01:55.090+00:00 | C61: OBSERVABILIDAD | D61: 200
A62: c19cd117-32043124-cd1fcd12 | B62: 2026-09-21T02:02:09.225+00:00 | C62: OBSERVABILIDAD | D62: 200
...

Sheet ERRORS
A1: ID_ERROR | B1: ID_REQUEST | C1: FECHA_HORA | D1: NODE | E1: ERROR | F1: ES_EJEMPLO
A2: 1787746656708 | C2: 8/26/2026 | E2: Error desconocido | F2: =FALSE() -> FALSE
A3: 9000001 | C3: 2026-09-15 | D3: AI Agent | E3: Timeout: la API del modelo no respondió dentro del tiempo esperado. | F3: =TRUE() -> TRUE
A4: 9000002 | C4: 2026-09-17 | D4: Transcribe audio or video | E4: Fallo al transcribir el archivo de audio recibido. | F4: =TRUE() -> TRUE
A5: 9000003 | C5: 2026-09-19 | D5: Get Context | E5: Error de conexión con Google Sheets al leer el historial del cliente. | F5: =TRUE() -> TRUE

Sheet DASHBOARD
A1: Dashboard de KPIs — Sistema de Presupuestos Automatizados
A3: KPIs Generales
A4: Total de consultas registradas | B4: =COUNTA(REQUEST!$F$2:$F$28) -> 27
A5: Clientes únicos con historial | B5: =COUNTA(CLIENTS!$A$2:$A$2) -> 1
A6: Total de evaluaciones del Juez | B6: =COUNTA(JUDGE!$O$2:$O$7) -> 6
A7: Total de llamadas a Workers | B7: =COUNTA(WORKER!$B$2:$B$63) -> 62
A8: Errores reales registrados | B8: =COUNTIF(ERRORS!$F$2:$F$5,FALSE()) -> 1
A9: Errores ilustrativos (no productivos) | B9: =COUNTIF(ERRORS!$F$2:$F$5,TRUE()) -> 3
A11: Estado de las Consultas (STATUS_NORMALIZADO)
A12: Estado | B12: Cantidad | C12: %
A13: APROBADO | B13: =COUNTIF(REQUEST!$H$2:$H$28,"APROBADO") -> 14 | C13: =B13/SUM($B$13:$B$17) -> 0.51851852
A14: CANCELADO | B14: =COUNTIF(REQUEST!$H$2:$H$28,"CANCELADO") -> 3 | C14: =B14/SUM($B$13:$B$17) -> 0.11111111
A15: EN_PROCESO | B15: =COUNTIF(REQUEST!$H$2:$H$28,"EN_PROCESO") -> 10 | C15: =B15/SUM($B$13:$B$17) -> 0.37037037
A16: SIN_CLASIFICAR | B16: =COUNTIF(REQUEST!$H$2:$H$28,"SIN_CLASIFICAR") -> 0 | C16: =B16/SUM($B$13:$B$17) -> 0
A17: SIN_DATO | B17: =COUNTIF(REQUEST!$H$2:$H$28,"SIN_DATO") -> 0 | C17: =B17/SUM($B$13:$B$17) -> 0
A19: Calidad del Juez (AI-as-a-Judge)
A20: Veredicto | B20: Cantidad | C20: %
A21: ACEPTADO | B21: =COUNTIF(JUDGE!$K$2:$K$7,"ACEPTADO") -> 3 | C21: =B21/SUM($B$21:$B$23) -> 0.5
A22: CORREGIR | B22: =COUNTIF(JUDGE!$K$2:$K$7,"CORREGIR") -> 2 | C22: =B22/SUM($B$21:$B$23) -> 0.33333333
A23: RECHAZADO | B23: =COUNTIF(JUDGE!$K$2:$K$7,"RECHAZADO") -> 1 | C23: =B23/SUM($B$21:$B$23) -> 0.16666667
A25: Exactitud factual promedio (1-5) | B25: =AVERAGE(JUDGE!$J$2:$J$7) -> 3.6666667
A26: Tasa de resolución autónoma (ACEPTADO) | B26: =COUNTIF(JUDGE!$K$2:$K$7,"ACEPTADO")/COUNTA(JUDGE!$O$2:$O$7) -> 0.5
A28: Categorías de Error Detectadas por el Juez
A29: Categoría | B29: Cantidad
A30: NINGUNA | B30: =COUNTIF(JUDGE!$I$2:$I$7,"NINGUNA") -> 3
A31: PRECIO_INEXISTENTE | B31: =COUNTIF(JUDGE!$I$2:$I$7,"PRECIO_INEXISTENTE") -> 0
A32: PRODUCTO_INVENTADO | B32: =COUNTIF(JUDGE!$I$2:$I$7,"PRODUCTO_INVENTADO") -> 0
A33: AFIRMACION_SIN_RESPALDO | B33: =COUNTIF(JUDGE!$I$2:$I$7,"AFIRMACION_SIN_RESPALDO") -> 3
A34: CONTRADICCION | B34: =COUNTIF(JUDGE!$I$2:$I$7,"CONTRADICCION") -> 0
A35: ID_PRODUCTO_INCORRECTO | B35: =COUNTIF(JUDGE!$I$2:$I$7,"ID_PRODUCTO_INCORRECTO") -> 0
A36: OMISION_FORMATO | B36: =COUNTIF(JUDGE!$I$2:$I$7,"OMISION_FORMATO") -> 0
A37: PUNTAJE_INCOHERENTE | B37: =COUNTIF(JUDGE!$I$2:$I$7,"PUNTAJE_INCOHERENTE") -> 0
A38: Categoría de error más frecuente (excluye NINGUNA) | B38: =IF(SUM($B$31:$B$37)=0,"Sin errores registrados",INDEX($A$31:$A$37,MATCH(MAX($B$31:$B$37),$B$31:$B$37,0))) -> AFIRMACION_SIN_RESPALDO
A40: Actividad de los Sub-workflows (Workers)
A41: Worker | B41: Llamadas
A42: OBSERVABILIDAD | B42: =COUNTIF(WORKER!$C$2:$C$63,"OBSERVABILIDAD") -> 33
A43: SUMMARY | B43: =COUNTIF(WORKER!$C$2:$C$63,"SUMMARY") -> 14
A44: JUDGE | B44: =COUNTIF(WORKER!$C$2:$C$63,"JUDGE") -> 15
A46: Producto Más Consultado (aproximado)
A47: Nota: el conteo usa coincidencia de texto porque algunas consultas registran más de un producto en una sola celda (ver ES_MULTIPRODUCTO en REQUEST / limitación documentada en la hoja DER).
...

Sheet DER
B2: DER — Esquema Relacional del Sistema de Presupuestos Automatizados
B4: RAG (Catálogo de productos)
B5: Campo | C5: Tipo | D5: Clave | E5: Descripción
B6: ID_PRODUCT | C6: texto | D6: PK | E6: Código único del producto (ej. HE1093).
B7: PRODUCTO | C7: texto | E7: Nombre y descripción del producto.
B8: PRECIO | C8: número | E8: Precio vigente (depurado: convertido de texto a número).
B9: ESTADO | C9: texto | E9: 'Publicado' o 'En Revisión'; solo se ofrecen los Publicados.
B11: CLIENTS (memoria de sesión por cliente)
B12: Campo | C12: Tipo | D12: Clave | E12: Descripción
B13: ID_SESSION | C13: número | D13: PK | E13: chat.id de Telegram; identifica al cliente.
B14: NAME | C14: texto | E14: Nombre del cliente.
B15: LAST_UPDATED | C15: fecha/hora | E15: Última actualización del resumen.
B16: SUMMARY | C16: texto | E16: Resumen consolidado de la conversación.
B17: STATUS | C17: texto | E17: Estado del caso (depurado: valor '""' vacío corregido).
B18: KEY_DATA | C18: texto (lista) | E18: Datos clave extraídos, serializados como texto.
B19: MESSAGE_COUNT | C19: número | E19: Cantidad de intercambios en la sesión.
B21: REQUEST (registro de consultas individuales)
B22: Campo | C22: Tipo | D22: Clave | E22: Descripción
B23: ID_REQUEST | C23: texto | D23: PK | E23: Identificador único del caso (traceId). Formato mixto por evolución del proyecto: timestamps antiguos vs. hex de 3 bloques actual.
B24: ID_PRODUCT | C24: texto | D24: FK → RAG | E24: Puede contener varios códigos separados por coma (ver ES_MULTIPRODUCTO).
B25: ES_MULTIPRODUCTO | C25: booleano | E25: Agregado en la depuración: True si ID_PRODUCT tiene más de un código (viola 1NF; limitación conocida del modelo actual).
B26: ID_SESSION | C26: número | D26: FK → CLIENTS | E26: Cliente que originó la consulta.
B27: QUESTION | C27: texto | E27: Consulta original del cliente.
B28: ANSWER | C28: texto | E28: Respuesta generada por el Manager.
B29: STATUS_RAW | C29: texto | E29: Valor crudo tal como se logueó (mezcla histórica de vocabularios; conservado para auditoría).
B30: STATUS_NORMALIZADO | C30: texto | E30: Agregado en la depuración: APROBADO / CANCELADO / EN_PROCESO.
B31: estado_veredicto | C31: texto | E31: Última copia del veredicto del Juez asociado (ver también hoja JUDGE).
B33: JUDGE (veredictos de AI-as-a-Judge)
B34: Campo | C34: Tipo | D34: Clave | E34: Descripción
B35: ID_REQUEST | C35: texto | D35: FK → REQUEST | E35: Puede ser nulo si la respuesta evaluada llegó vacía.
B36: QUESTION / ANSWER / CONTEXT | C36: texto | E36: Insumos que tuvo el Juez para evaluar.
B37: UMBRAL | C37: número | E37: Máximo de reintentos permitido antes de forzar RECHAZADO.
B38: inconsistencias_detectadas / afirmaciones_sin_respaldo | C38: texto (lista) | E38: Arrays serializados como texto.
B39: justificacion / critica | C39: texto | E39: Explicación del puntaje y sugerencia de corrección.
B40: categoria_error | C40: texto | E40: Una de 8 categorías cerradas (enum).
B41: exactitud_factual | C41: número (1-5) | E41: Puntaje de exactitud.
B42: estado_veredicto | C42: texto | E42: ACEPTADO / CORREGIR / RECHAZADO.
B43: verbosidad_excesiva | C43: booleano | E43: Si la respuesta fue más larga de lo necesario.
B44: TRYS | C44: número | E44: Intento número N para este caso.
B45: datetime | C45: fecha/hora | E45: Momento del veredicto.
...
